Workbook

Sheet Ballrooms
A1: Room Name | B1: Hardware Type | C1: Hardware ID | D1: Unique ID | E1: Network Cable | F1: Power Cable
A2: Ballroom A | B2: Switch
A3: Ballroom A | B3: AP's (old style)
A4: Ballroom A | B4: AP's (old style)
A5: Ballroom A | B5: AP's (old style)
A6: Ballroom A | B6: Camera | C6: AV EQUIPMENT
A7: Ballroom A | B7: Mixer | C7: AV EQUIPMENT
A8: Ballroom A | B8: 10' cable | C8: For Speaker Table
A9: Ballroom A | B9: 15' cable | C9: For Podium
A10: Ballroom B | B10: Switch
A11: Ballroom B | B11: AP's (old style)
A12: Ballroom B | B12: AP's (old style)
A13: Ballroom B | B13: AP's (old style)
A14: Ballroom B | B14: Camera | C14: AV EQUIPMENT
A15: Ballroom B | B15: Mixer | C15: AV EQUIPMENT
A16: Ballroom B | B16: 15' cable | C16: For Speaker Table
A17: Ballroom B | B17: 25' cable | C17: For Podium
A18: Ballroom C | B18: Switch
A19: Ballroom C | B19: AP's (old style)
A20: Ballroom C | B20: AP's (old style)
A21: Ballroom C | B21: AP's (old style)
A22: Ballroom C | B22: Camera | C22: AV EQUIPMENT
A23: Ballroom C | B23: Mixer | C23: AV EQUIPMENT
A24: Ballroom C | B24: 45' cable | C24: For Speaker Table
A25: Ballroom C | B25: 60' cable | C25: For Podium
A26: Ballroom D/E | B26: Switch
A27: Ballroom D/E | B27: AP's (old style)
A28: Ballroom D/E | B28: AP's (old style)
A29: Ballroom D/E | B29: AP's (old style)
A30: Ballroom D/E | B30: Camera | C30: AV EQUIPMENT
A31: Ballroom D/E | B31: Mixer | C31: AV EQUIPMENT
A32: Ballroom D/E | B32: 100' cable | C32: For Speaker Table
A33: Ballroom D/E | B33: 40' cable | C33: For Podium

Sheet Inventory List
A1: ITEM TYPE | B1: TOTAL QUANTITY | C1: QUANTITY IN TUBS | D1: ID CODE
A2: ETHERNET CABLES
A3: 5' cable | C3: =COUNTIF(Ballrooms!$B$2:$B$100, A3) -> 0
A4: 10' cable | C4: =COUNTIF(Ballrooms!$B$2:$B$100, A4) -> 1
A5: 15' cable | C5: =COUNTIF(Ballrooms!$B$2:$B$100, A5) -> 2
A6: 20' cable | C6: =COUNTIF(Ballrooms!$B$2:$B$100, A6) -> 0
A7: 25' cable | C7: =COUNTIF(Ballrooms!$B$2:$B$100, A7) -> 1
A8: 30' cable | C8: =COUNTIF(Ballrooms!$B$2:$B$100, A8) -> 0
A9: 35' cable | C9: =COUNTIF(Ballrooms!$B$2:$B$100, A9) -> 0
A10: 40' cable | C10: =COUNTIF(Ballrooms!$B$2:$B$100, A10) -> 1
A11: 45' cable | C11: =COUNTIF(Ballrooms!$B$2:$B$100, A11) -> 1
A12: 50' cable | C12: =COUNTIF(Ballrooms!$B$2:$B$100, A12) -> 0
A13: 55' cable | C13: =COUNTIF(Ballrooms!$B$2:$B$100, A13) -> 0
A14: 60' cable | C14: =COUNTIF(Ballrooms!$B$2:$B$100, A14) -> 1
... A24: 160'+ cable | C24: =COUNTIF(Ballrooms!$B$2:$B$100, A24) -> 0
A25: HARDWARE
A26: PI 1 | C26: =COUNTIF(Ballrooms!$B$2:$B$100, A26) -> 0
A27: Pi 2 | C27: =COUNTIF(Ballrooms!$B$2:$B$100, A27) -> 0
A28: PI 4 | B28: 30 | C28: =COUNTIF(Ballrooms!$B$2:$B$100, A28) -> 0
A29: Monitor | C29: =COUNTIF(Ballrooms!$B$2:$B$100, A29) -> 0
A30: MicroSD - Imagin Server Image | C30: =COUNTIF(Ballrooms!$B$2:$B$100, A30) -> 0
A31: MicroSD - Desktop Image | C31: =COUNTIF(Ballrooms!$B$2:$B$100, A31) -> 0
A32: MicroSD - Sign & Reg Image | C32: =COUNTIF(Ballrooms!$B$2:$B$100, A32) -> 0
A33: Keyboard | C33: =COUNTIF(Ballrooms!$B$2:$B$100, A33) -> 0
A34: Mouse | C34: =COUNTIF(Ballrooms!$B$2:$B$100, A34) -> 0
A35: AP's (old style) | C35: =COUNTIF(Ballrooms!$B$2:$B$100, A35) -> 12
A36: AP's (new style) | C36: =COUNTIF(Ballrooms!$B$2:$B$100, A36) -> 0
A37: Switch | C37: =COUNTIF(Ballrooms!$B$2:$B$100, A37) -> 4
A38: Server | C38: =COUNTIF(Ballrooms!$B$2:$B$100, A38) -> 0
A39: Printer | C39: =COUNTIF(Ballrooms!$B$2:$B$100, A39) -> 0
A40: POWER CABLES
A41: Old PI power | C41: =COUNTIF(Ballrooms!$B$2:$B$100, A41) -> 0
A42: PI power (4B) | B42: 30 | C42: =COUNTIF(Ballrooms!$B$2:$B$100, A42) -> 0
A43: Monitor Power Cord | C43: =COUNTIF(Ballrooms!$B$2:$B$100, A43) -> 0
A44: AP Power Supply (old) | C44: =COUNTIF(Ballrooms!$B$2:$B$100, A44) -> 0
A45: AP Power Supply (new) | C45: =COUNTIF(Ballrooms!$B$2:$B$100, A45) -> 0
A46: Powerstrip - Short | C46: =COUNTIF(Ballrooms!$B$2:$B$100, A46) -> 0
A47: Powerstrip - Long | C47: =COUNTIF(Ballrooms!$B$2:$B$100, A47) -> 0
A48: Extenstion cable - Short | C48: =COUNTIF(Ballrooms!$B$2:$B$100, A48) -> 0
A49: Extension cord - Medium | C49: =COUNTIF(Ballrooms!$B$2:$B$100, A49) -> 0
...
